
<robot name="simple_arm" xmlns:xacro="http://wiki.ros.org/xacro">
    <link name="base_link">
        <visual>
            <origin xyz="0 0 0.025"/>
            <geometry>
                <cylinder radius="0.2" length="0.05"/>
            </geometry>
            <material name="gray">
                <color rgba="0.5 0.5 0.5 1"/>
            </material>
        </visual>
    </link>
    <joint name="joint1" type="revolute">
        <parent link="base_link"/>
        <child link="link1"/>
        <origin xyz="0 0 0.05"/>
        <axis xyz="0 0 1"/>
        <limit effort="5" velocity="2.0" lower="0" upper="3.14"/>
    </joint>
    <link name="link1">
        <visual>
            <origin xyz="0 0 0.075"/>
            <geometry>
                <cylinder radius="0.14" length="0.15"/>
            </geometry>
            <material name="blue">
                <color rgba="0 0 1 1"/>
            </material>
        </visual>
    </link>
    <joint name="joint2" type="revolute">
        <parent link="link1"/>
        <child link="link2"/>
        <origin xyz="0 0 0.15"/>
        <axis xyz="0 0 1"/>
        <limit effort="5" velocity="2.0" lower="0" upper="3.14"/>
    </joint>
    <link name="link2">
        <visual>
            <origin xyz="0 0 0.075"/>
            <geometry>
                <cylinder radius="0.14" length="0.15"/>
            </geometry>
            <material name="red">
                <color rgba="1 0 0 1"/>
            </material>
        </visual>
    </link>
    <joint name="joint3" type="revolute">
        <parent link="link2"/>
        <child link="link3"/>
        <origin xyz="0 0 0.15"/>
        <axis xyz="1 0 0"/>
        <limit effort="5" velocity="2.0" lower="-1.5" upper="1.5"/>
    </joint>
    <link name="link3">
        
        <visual>
            <origin xyz="0 0 0.15"/>
            <geometry>
                <cylinder radius="0.12" length="0.3"/>
            </geometry>
            <material name="red">
                <color rgba="1 0 0 1"/>
            </material>
        </visual>
    </link>
    <joint name="joint4" type="revolute">
        <parent link="link3"/>
        <child link="link4"/>
        <origin xyz="0 0 0.3"/>
        <axis xyz="1 0 0"/>
        <limit effort="5" velocity="2.0" lower="-1.5" upper="1.5"/>
    </joint>
    <link name="link4">
        
        <visual>
            <origin xyz="0 0 0.05"/>
            <geometry>
                <cylinder radius="0.1" length="0.1"/>
            </geometry>
            <material name="red">
                <color rgba="1 0 1 1"/>
            </material>
        </visual>
    </link>
    <joint name="joint5" type="revolute">
        <parent link="link4"/>
        <child link="link5"/>
        <origin xyz="0 0 0.1"/>
        <axis xyz="0 0 1"/>
        <limit effort="5" velocity="2.0" lower="-1.5" upper="1.5"/>
    </joint>
    <link name="link5">
        
        <visual>
            <origin xyz="0 0 0.05"/>
            <geometry>
                <cylinder radius="0.1" length="0.1"/>
            </geometry>
            <material name="red">
                <color rgba="1 1 0 1"/>
            </material>
        </visual>
    </link>
    <joint name="joint6" type="revolute">
        <parent link="link5"/>
        <child link="link6"/>
        <origin xyz="0 0 0.1"/>
        <axis xyz="1 0 0"/>
        <limit effort="5" velocity="2.0" lower="-1.5" upper="1.5"/>
    </joint>
    <link name="link6">
        
        <visual>
            <origin xyz="0 0 0.04"/>
            <geometry>
                <cylinder radius="0.08" length="0.08"/>
            </geometry>
            <material name="red">
                <color rgba="0.5 0.5 0 1"/>
            </material>
        </visual>
    </link>
    <joint name="joint7" type="revolute">
        <parent link="link6"/>
        <child link="link7"/>
        <origin xyz="0 0 0.08"/>
        <axis xyz="0 0 1"/>
        <limit effort="5" velocity="2.0" lower="-1.5" upper="1.5"/>
    </joint>
    <link name="link7">
        
        <visual>
            <origin xyz="0 0 0.035"/>
            <geometry>
                <cylinder radius="0.05" length="0.07"/>
            </geometry>
            <material name="red">
                <color rgba="1 0.5 0 1"/>
            </material>
        </visual>
    </link>
    <joint name="joint8" type="fixed">
        <parent link="link7"/>
        <child link="link8"/>
        <origin xyz="0 0 0.07"/>
        <axis xyz="0 0 1"/>
        <limit effort="5" velocity="2.0" lower="-1.5" upper="1.5"/>
    </joint>
    <link name="link8">
        
        <visual>
            <origin xyz="0 0 0.02"/>
            <geometry>
                <box size="0.02 0.02 0.04"/>
            </geometry>
            <material name="red">
                <color rgba="1 1 0 1"/>
            </material>
        </visual>
    </link>
    <joint name="joint9" type="prismatic">
        <parent link="link8"/>
        <child link="link9"/>
        <origin xyz="0.0125 0 0.04"/>
        <axis xyz="1 0 0"/>
        <limit effort="5" velocity="2.0" lower="0" upper="0.02"/>
    </joint>
    <link name="link9">
        
        <visual>
            <origin xyz="0 0 0.02"/>
            <geometry>
                <box size="0.005 0.05 0.05"/>
            </geometry>
            <material name="red">
                <color rgba="1 1 0 1"/>
            </material>
        </visual>
    </link>
    <joint name="joint10" type="prismatic">
        <parent link="link8"/>
        <child link="link10"/>
        <origin xyz="-0.0125 0 0.04"/>
        <axis xyz="1 0 0"/>
        <limit effort="5" velocity="2.0" lower="-0.02" upper="0"/>
    </joint>
    <link name="link10">
        
        <visual>
            <origin xyz="0 0 0.02"/>
            <geometry>
                <box size="0.005 0.05 0.05"/>
            </geometry>
            <material name="red">
                <color rgba="1 1 0 1"/>
            </material>
        </visual>
    </link>
</robot>